<?xml version="1.0"?>


<robot name="dogbot" xmlns:xacro="http://www.ros.org/wiki/xacro">




<!-- pre-defined colors -->
<material name="tiffany">
    <color rgba="0.039 0.729 0.709 1"/>
  </material>
  <material name="black">
    <color rgba="0 0 0 1"/>
  </material>
  <material name="white">
    <color rgba="1 1 1 1"/>
  </material>
  <material name="white_1">
    <color rgba="1 1 1 0.7"/>
  </material>


    <!-- body part -->
  <link name = "base_link">
   <visual>
    <geometry>
     <box size="1 0.3 0.2" />
    </geometry>

     <material name = "tiffany"/>
     <origin rpy="0 0 0" xyz="0 0 0.5"/>
    </visual>

    <collision>
     <origin rpy="0 0 0" xyz="0 0 0.5"/>
    <geometry>
     <box size="1 0.3 0.2" />
    </geometry>
    </collision>

    <inertial>
     <origin rpy="0 0 0" xyz="0 0 0.5"/>
      <mass value="0.03" />
      <inertia ixx="0.4" ixy="0.0" ixz="0.0" iyy="0.4" iyz="0.0" izz="0.4" />
  </inertial>
   </link>

<!-- camera -->
<!--
<link name = "camera_link">
   <visual>
     <material name = "white_1"/>
     <origin rpy="0 0 0" xyz="0.1 0 0.15"/>
    <geometry>
     <box size="0.3 0.3 0.1" />
    </geometry>
    </visual>

    <collision>
     <origin rpy="0 0 0" xyz="0.1 0 0.15"/>
    <geometry>
     <box size="0.3 0.3 0.1" />
    </geometry>
    </collision>

    <inertial>
     <origin rpy="0 0 0" xyz="0.1 0 0.15"/>
      <mass value="0.01" />
      <inertia ixx="0.4" ixy="0.0" ixz="0.0" iyy="0.4" iyz="0.0" izz="0.4" />
  </inertial>
   </link>
-->
<!-- import camera -->
    <xacro:include filename="$(find dogbot)/urdf/camera.xacro"/>



  <joint name="camera_joint" type="fixed">
    <parent link="base_link"/>
    <child link="camera_link"/>
    <origin xyz="0.1 0 0.19"/>
     <xacro:web_camera prefix="camera"/>
  </joint>



<!-- front right -->
  <link name = "front_leg_right">
   <visual>
     <material name = "white"/>
     <origin rpy="0 0 0" xyz="0 0 -0.15"/>
    <geometry>
     <box size="0.1 0.1 0.3" />
    </geometry>
    </visual>

    <collision>
     <origin rpy="0 0 0" xyz="0 0 -0.15"/>
    <geometry>
     <box size="0.1 0.1 0.3" />
    </geometry>
    </collision>

    <inertial>
     <origin rpy="0 0 0" xyz="0 0 -0.15"/>
      <mass value="0.03" />
      <inertia ixx="0.4" ixy="0.0" ixz="0.0" iyy="0.4" iyz="0.0" izz="0.4" />
  </inertial>
   </link>


  <joint name="joint_f_r_1" type="revolute">
    <parent link="base_link"/>
    <child link="front_leg_right"/>
    <origin xyz="0.2 0.2 0.5"/>
    <axis xyz="0 1 0"/>
    <limit lower="-1" upper="1" effort="4" velocity="2" />
  </joint>
 <transmission name="trans1">
    <type>transmission_interface/SimpleTransmission</type>
    <joint name="joint_f_r_1">
      <hardwareInterface>EffortJointInterface</hardwareInterface>
    </joint>
    <actuator name="motor1">
       <hardwareInterface>EffortJointInterface</hardwareInterface>
       <mechanismReduction>1</mechanismReduction>
    </actuator>
 </transmission>


  <link name = "front_leg_right2">
   <visual>
    <geometry>
     <box size="0.07 0.07 0.4" />
    </geometry>
     <material name = "white"/>
     <origin rpy="0 0 0" xyz="0 0 -0.25"/>
    </visual>

    <collision>
     <origin rpy="0 0 0" xyz="0 0 -0.25"/>
    <geometry>
     <box size="0.07 0.07 0.4" />
    </geometry>
    </collision>

    <inertial>
     <origin rpy="0 0 0" xyz="0 0 -0.25"/>
      <mass value="0.03" />
      <inertia ixx="0.4" ixy="0.0" ixz="0.0" iyy="0.4" iyz="0.0" izz="0.4" />
  </inertial>
   </link>

  <joint name="joint_f_r_2" type="revolute">
    <parent link="front_leg_right"/>
    <child link="front_leg_right2"/>
    <origin xyz="0 0 -0.3"/>
    <axis xyz="0 1 0"/>
    <limit lower="-2" upper="0" effort="4" velocity="2" />
  </joint>
 <transmission name="trans2">
    <type>transmission_interface/SimpleTransmission</type>
    <joint name="joint_f_r_2">
      <hardwareInterface>EffortJointInterface</hardwareInterface>
    </joint>
    <actuator name="motor2">
       <hardwareInterface>EffortJointInterface</hardwareInterface>
       <mechanismReduction>1</mechanismReduction>
    </actuator>
 </transmission>


<!-- front left -->
  <link name = "front_leg_left">
   <visual>
    <geometry>
     <box size="0.1 0.1 0.3" />
    </geometry>
     <material name = "white"/>
     <origin rpy="0 0 0" xyz="0 0 -0.15"/>
    </visual>

    <collision>
     <origin rpy="0 0 0" xyz="0 0 -0.15"/>
     <geometry>
     <box size="0.1 0.1 0.3" />
     </geometry>
    </collision>

    <inertial>
     <origin rpy="0 0 0" xyz="0 0 -0.15"/>
      <mass value="0.03" />
      <inertia ixx="0.4" ixy="0.0" ixz="0.0" iyy="0.4" iyz="0.0" izz="0.4" />
  </inertial>
   </link>


  <joint name="joint_f_l_1" type="revolute">
    <parent link="base_link"/>
    <child link="front_leg_left"/>
    <origin rpy="0 0 0 " xyz="0.2 -0.2 0.5"/>
    <axis xyz="0 1 0"/>
    <limit lower="-1" upper="1" effort="4" velocity="2" />
  </joint>
 <transmission name="trans3">
    <type>transmission_interface/SimpleTransmission</type>
    <joint name="joint_f_l_1">
      <hardwareInterface>EffortJointInterface</hardwareInterface>
    </joint>
    <actuator name="motor3">
       <hardwareInterface>EffortJointInterface</hardwareInterface>
       <mechanismReduction>1</mechanismReduction>
    </actuator>
 </transmission>



  <link name = "front_leg_left2">
   <visual>
    <geometry>
     <box size="0.07 0.07 0.4" />
    </geometry>
     <material name = "white"/>
     <origin rpy="0 0 0" xyz="0 0 -0.25"/>
    </visual>

    <collision>
     <origin rpy="0 0 0" xyz="0 0 -0.25"/>
     <geometry>
     <box size="0.07 0.07 0.4" />
     </geometry>
    </collision>

    <inertial>
     <origin rpy="0 0 0" xyz="0 0 -0.25"/>
      <mass value="0.03" />
      <inertia ixx="0.4" ixy="0.0" ixz="0.0" iyy="0.4" iyz="0.0" izz="0.4" />
  </inertial>
   </link>

  <joint name="joint_f_l_2" type="revolute">
    <parent link="front_leg_left"/>
    <child link="front_leg_left2"/>
    <origin xyz="0 0 -0.3"/>
    <axis xyz="0 1 0"/>
    <limit lower="-2" upper="0" effort="4" velocity="2" />
  </joint>
 <transmission name="trans4">
    <type>transmission_interface/SimpleTransmission</type>
    <joint name="joint_f_l_2">
      <hardwareInterface>EffortJointInterface</hardwareInterface>
    </joint>
    <actuator name="motor4">
       <hardwareInterface>EffortJointInterface</hardwareInterface>
       <mechanismReduction>1</mechanismReduction>
    </actuator>
 </transmission>


<!-- back right -->

  <link name = "back_leg_right">
   <visual>
    <geometry>
     <box size="0.1 0.1 0.3" />
    </geometry>
     <material name = "white"/>
     <origin rpy="0 0 0" xyz="0 0 -0.15"/>
    </visual>

    <collision>
     <origin rpy="0 0 0" xyz="0 0 -0.15"/>
     <geometry>
     <box size="0.1 0.1 0.3" />
     </geometry>
    </collision>

    <inertial>
     <origin rpy="0 0 0" xyz="0 0 -0.15"/>
      <mass value="0.03" />
      <inertia ixx="0.4" ixy="0.0" ixz="0.0" iyy="0.4" iyz="0.0" izz="0.4" />
  </inertial>
   </link>


  <joint name="joint_b_r_1" type="revolute">
    <parent link="base_link"/>
    <child link="back_leg_right"/>
    <origin xyz="-0.2 0.2 0.5"/>
    <axis xyz="0 1 0"/>
    <limit lower="-1" upper="1" effort="4" velocity="2" />
  </joint>
 <transmission name="trans5">
    <type>transmission_interface/SimpleTransmission</type>
    <joint name="joint_b_r_1">
      <hardwareInterface>EffortJointInterface</hardwareInterface>
    </joint>
    <actuator name="motor5">
       <hardwareInterface>EffortJointInterface</hardwareInterface>
       <mechanismReduction>1</mechanismReduction>
    </actuator>
 </transmission>



  <link name = "back_leg_right2">
   <visual>
    <geometry>
     <box size="0.07 0.07 0.4" />
    </geometry>
     <material name = "white"/>
     <origin rpy="0 0 0" xyz="0 0 -0.25"/>
    </visual>

    <collision>
     <origin rpy="0 0 0" xyz="0 0 -0.25"/>
     <geometry>
     <box size="0.07 0.07 0.4" />
     </geometry>
    </collision>

    <inertial>
     <origin rpy="0 0 0" xyz="0 0 -0.25"/>
      <mass value="0.03" />
      <inertia ixx="0.4" ixy="0.0" ixz="0.0" iyy="0.4" iyz="0.0" izz="0.4" />
  </inertial>
   </link>

  <joint name="joint_b_r_2" type="revolute">
    <parent link="back_leg_right"/>
    <child link="back_leg_right2"/>
    <origin xyz="0 0 -0.3"/>
    <axis xyz="0 1 0"/>
    <limit lower="-2" upper="0" effort="4" velocity="2" />
  </joint>
 <transmission name="trans6">
    <type>transmission_interface/SimpleTransmission</type>
    <joint name="joint_b_r_2">
      <hardwareInterface>EffortJointInterface</hardwareInterface>
    </joint>
    <actuator name="motor6">
       <hardwareInterface>EffortJointInterface</hardwareInterface>
       <mechanismReduction>1</mechanismReduction>
    </actuator>
 </transmission>

<!-- back left -->
  <link name = "back_leg_left">
   <visual>
    <geometry>
     <box size="0.1 0.1 0.3" />
    </geometry>
     <material name = "white"/>
     <origin rpy="0 0 0" xyz="0 0 -0.15"/>
    </visual>

    <collision>
     <origin rpy="0 0 0" xyz="0 0 -0.15"/>
     <geometry>
     <box size="0.1 0.1 0.3" />
     </geometry>
    </collision>

    <inertial>
     <origin rpy="0 0 0" xyz="0 0 -0.15"/>
      <mass value="0.03" />
      <inertia ixx="0.4" ixy="0.0" ixz="0.0" iyy="0.4" iyz="0.0" izz="0.4" />
  </inertial>
   </link>


  <joint name="joint_b_l_1" type="revolute">
    <parent link="base_link"/>
    <child link="back_leg_left"/>
    <origin xyz="-0.2 -0.2 0.5"/>
    <axis xyz="0 1 0"/>
    <limit lower="-1" upper="1" effort="4" velocity="2" />
  </joint>
 <transmission name="trans7">
    <type>transmission_interface/SimpleTransmission</type>
    <joint name="joint_b_l_1">
      <hardwareInterface>EffortJointInterface</hardwareInterface>
    </joint>
    <actuator name="motor7">
       <hardwareInterface>EffortJointInterface</hardwareInterface>
       <mechanismReduction>1</mechanismReduction>
    </actuator>
 </transmission>



  <link name = "back_leg_left2">
   <visual>
    <geometry>
     <box size="0.07 0.07 0.4" />
    </geometry>
     <material name = "white"/>
     <origin rpy="0 0 0" xyz="0 0 -0.25"/>
    </visual>

    <collision>
     <origin rpy="0 0 0" xyz="0 0 -0.25"/>
     <geometry>
     <box size="0.07 0.07 0.4" />
     </geometry>
    </collision>

    <inertial>
     <origin rpy="0 0 0" xyz="0 0 -0.25"/>
      <mass value="0.03" />
      <inertia ixx="0.4" ixy="0.0" ixz="0.0" iyy="0.4" iyz="0.0" izz="0.4" />
  </inertial>
   </link>

  <joint name="joint_b_l_2" type="revolute">
    <parent link="back_leg_left"/>
    <child link="back_leg_left2"/>
    <origin xyz="0 0 -0.3"/>
    <axis xyz="0 1 0"/>
    <limit lower="-2" upper="0" effort="4" velocity="2" />
  </joint>
 <transmission name="trans8">
    <type>transmission_interface/SimpleTransmission</type>
    <joint name="joint_b_l_2">
      <hardwareInterface>EffortJointInterface</hardwareInterface>
    </joint>
    <actuator name="motor8">
       <hardwareInterface>EffortJointInterface</hardwareInterface>
       <mechanismReduction>1</mechanismReduction>
    </actuator>
 </transmission>

<!-- -->
<gazebo>
    <self_collide>1</self_collide>
    <plugin name="gazebo_ros_control" filename="libgazebo_ros_control.so">
      <robotNamespace>/dogbot</robotNamespace>
    </plugin>
</gazebo>

</robot>
